Workbook

Sheet README
A1: CUSTOMER CHURN ANALYSIS
A2: Purpose | B2: Analyze customer churn patterns and identify higher-risk contracts, regions, tenure groups and customer types.
A3: How to use | B3: Replace or extend the records in Customer_Data while keeping the same columns. Analysis and Dashboard formulas use that data.
A4: Included | B4: Customer-level data, churn KPIs, churn by contract, region, tenure, customer type, revenue at risk and data-quality checks.
A5: Project title | B5: Customer Churn Pattern Analysis Dashboard
A6: Note | B6: No detailed project brief or dataset was provided, so realistic sample data is included to demonstrate the analysis.

Sheet Customer_Data
A1: Customer ID | B1: Join Date | C1: Region | D1: Customer Type | E1: Contract | F1: Tenure Months | G1: Monthly Charges | H1: Support Tickets | I1: Payment Method | J1: Churned | K1: Churn Date | L1: Revenue at Risk
A2: C0001 | B2: 45729 | C2: North | D2: Individual | E2: One Year | F2: 17 | G2: 38.97 | H2: 0 | I2: Card | J2: No | L2: 0
A3: C0002 | B3: 46115 | C3: South | D3: Individual | E3: One Year | F3: 4 | G3: 37.86 | H3: 1 | I3: Card | J3: No | L3: 0
A4: C0003 | B4: 45218 | C4: West | D4: Individual | E4: Two Year | F4: 34 | G4: 37.47 | H4: 4 | I4: Card | J4: No | L4: 0
A5: C0004 | B5: 45922 | C5: South | D5: Individual | E5: One Year | F5: 11 | G5: 56.13 | H5: 2 | I5: Direct Debit | J5: No | L5: 0
A6: C0005 | B6: 45201 | C6: South | D6: Small Business | E6: One Year | F6: 34 | G6: 98.94 | H6: 2 | I6: Bank Transfer | J6: No | L6: 0
A7: C0006 | B7: 45374 | C7: South | D7: Individual | E7: One Year | F7: 29 | G7: 52.54 | H7: 5 | I7: Direct Debit | J7: No | L7: 0
A8: C0007 | B8: 46101 | C8: North | D8: Individual | E8: Monthly | F8: 5 | G8: 41.2 | H8: 0 | I8: Direct Debit | J8: No | L8: 0
A9: C0008 | B9: 45188 | C9: East | D9: Small Business | E9: One Year | F9: 35 | G9: 109.45 | H9: 7 | I9: Bank Transfer | J9: No | L9: 0
A10: C0009 | B10: 44966 | C10: West | D10: Enterprise | E10: One Year | F10: 42 | G10: 151.64 | H10: 2 | I10: Bank Transfer | J10: No | L10: 0
A11: C0010 | B11: 46004 | C11: East | D11: Individual | E11: Two Year | F11: 8 | G11: 47.2 | H11: 0 | I11: Bank Transfer | J11: No | L11: 0
A12: C0011 | B12: 45041 | C12: East | D12: Individual | E12: One Year | F12: 40 | G12: 48.53 | H12: 5 | I12: Bank Transfer | J12: No | L12: 0
A13: C0012 | B13: 45730 | C13: East | D13: Enterprise | E13: Monthly | F13: 17 | G13: 189.21 | H13: 2 | I13: Card | J13: No | L13: 0
... A15: C0014 | B15: 46154 | C15: East | D15: Individual | E15: One Year | F15: 3 | G15: 52.24 | H15: 2 | I15: Direct Debit | J15: No | L15: 0
A16: C0015 | B16: 45163 | C16: West | D16: Small Business | E16: Monthly | F16: 36 | G16: 78.52 | H16: 3 | I16: Bank Transfer | J16: Yes | K16: 45620 | L16: 78.52
A17: C0016 | B17: 45333 | C17: North | D17: Individual | E17: Monthly | F17: 30 | G17: 40.76 | H17: 2 | I17: Direct Debit | J17: Yes | K17: 45735 | L17: 40.76
A18: C0017 | B18: 44964 | C18: West | D18: Individual | E18: One Year | F18: 42 | G18: 66.1 | H18: 1 | I18: Bank Transfer | J18: Yes | K18: 45993 | L18: 66.1
A19: C0018 | B19: 46122 | C19: North | D19: Individual | E19: Monthly | F19: 4 | G19: 46.79 | H19: 2 | I19: Direct Debit | J19: Yes | K19: 46172 | L19: 46.79
A20: C0019 | B20: 45033 | C20: East | D20: Individual | E20: One Year | F20: 40 | G20: 64.8 | H20: 3 | I20: Card | J20: No | L20: 0
A21: C0020 | B21: 45912 | C21: South | D21: Small Business | E21: One Year | F21: 11 | G21: 105.55 | H21: 1 | I21: Bank Transfer | J21: No | L21: 0
A22: C0021 | B22: 45591 | C22: South | D22: Individual | E22: One Year | F22: 22 | G22: 59.31 | H22: 3 | I22: Card | J22: No | L22: 0
A23: C0022 | B23: 45062 | C23: East | D23: Individual | E23: One Year | F23: 39 | G23: 66.13 | H23: 5 | I23: Direct Debit | J23: No | L23: 0
A24: C0023 | B24: 45811 | C24: South | D24: Individual | E24: Monthly | F24: 14 | G24: 42.2 | H24: 4 | I24: Card | J24: No | L24: 0
A25: C0024 | B25: 46185 | C25: North | D25: Enterprise | E25: Monthly | F25: 2 | G25: 192.96 | H25: 6 | I25: Card | J25: No | L25: 0
A26: C0025 | B26: 46067 | C26: East | D26: Individual | E26: One Year | F26: 6 | G26: 66.61 | H26: 1 | I26: Direct Debit | J26: No | L26: 0
A27: C0026 | B27: 45356 | C27: North | D27: Individual | E27: One Year | F27: 29 | G27: 50.66 | H27: 4 | I27: Direct Debit | J27: No | L27: 0
A28: C0027 | B28: 46185 | C28: South | D28: Enterprise | E28: Monthly | F28: 2 | G28: 146.7 | H28: 4 | I28: Bank Transfer | J28: Yes | K28: 46219 | L28: 146.7
A29: C0028 | B29: 45383 | C29: East | D29: Individual | E29: Monthly | F29: 28 | G29: 43.58 | H29: 0 | I29: Bank Transfer | J29: No | L29: 0
A30: C0029 | B30: 46208 | C30: North | D30: Enterprise | E30: Monthly | F30: 1 | G30: 201.73 | H30: 0 | I30: Direct Debit | J30: No | L30: 0
A31: C0030 | B31: 45540 | C31: North | D31: Small Business | E31: One Year | F31: 23 | G31: 110.34 | H31: 1 | I31: Card | J31: No | L31: 0
A32: C0031 | B32: 45367 | C32: North | D32: Enterprise | E32: Monthly | F32: 29 | G32: 229.97 | H32: 1 | I32: Direct Debit | J32: No | L32: 0
A33: C0032 | B33: 45023 | C33: East | D33: Individual | E33: One Year | F33: 40 | G33: 51.99 | H33: 3 | I33: Card | J33: No | L33: 0
A34: C0033 | B34: 46101 | C34: South | D34: Enterprise | E34: Monthly | F34: 5 | G34: 208.03 | H34: 4 | I34: Bank Transfer | J34: Yes | K34: 46197 | L34: 208.03
A35: C0034 | B35: 45509 | C35: West | D35: Individual | E35: Monthly | F35: 24 | G35: 45.95 | H35: 1 | I35: Bank Transfer | J35: No | L35: 0
A36: C0035 | B36: 45038 | C36: East | D36: Individual | E36: Two Year | F36: 40 | G36: 40.87 | H36: 2 | I36: Card | J36: No | L36: 0
A37: C0036 | B37: 46077 | C37: North | D37: Small Business | E37: Two Year | F37: 6 | G37: 82.26 | H37: 0 | I37: Card | J37: No | L37: 0
A38: C0037 | B38: 45640 | C38: West | D38: Small Business | E38: Monthly | F38: 20 | G38: 94.47 | H38: 5 | I38: Bank Transfer | J38: No | L38: 0
A39: C0038 | B39: 46174 | C39: West | D39: Small Business | E39: Monthly | F39: 2 | G39: 90.61 | H39: 4 | I39: Card | J39: No | L39: 0
A40: C0039 | B40: 45325 | C40: East | D40: Small Business | E40: Monthly | F40: 30 | G40: 121.08 | H40: 3 | I40: Direct Debit | J40: No | L40: 0
A41: C0040 | B41: 45843 | C41: West | D41: Enterprise | E41: Monthly | F41: 13 | G41: 179.16 | H41: 4 | I41: Card | J41: No | L41: 0
...

Sheet Analysis
A1: AUTOMATED CHURN ANALYSIS
A3: KPI | B3: Value
A4: Total Customers | B4: =COUNTA(Customer_Data!A2:A301) -> 300
A5: Churned Customers | B5: =COUNTIF(Customer_Data!J2:J301,"Yes") -> 65
A6: Churn Rate | B6: =IFERROR(B5/B4,0) -> 0.21666667
A7: Monthly Revenue at Risk | B7: =SUMIF(Customer_Data!J2:J301,"Yes",Customer_Data!L2:L301) -> 6353.49
A8: Avg Tenure - Churned | B8: =IFERROR(AVERAGEIF(Customer_Data!J2:J301,"Yes",Customer_Data!F2:F301),0) -> 17.861538
A11: CHURN BY CONTRACT | G11: CHURN BY REGION
A12: Contract | B12: Customers | C12: Churned | D12: Churn Rate | E12: Revenue at Risk | G12: Region | H12: Customers | I12: Churned | J12: Churn Rate
A13: Monthly | B13: =COUNTIF(Customer_Data!$E$2:$E$301,A13) -> 168 | C13: =COUNTIFS(Customer_Data!$E$2:$E$301,A13,Customer_Data!$J$2:$J$301,"Yes") -> 45 | D13: =IFERROR(C13/B13,0) -> 0.26785714 | E13: =SUMIFS(Customer_Data!$L$2:$L$301,Customer_Data!$E$2:$E$301,A13,Customer_Data!$J$2:$J$301,"Yes") -> 4563.78 | G13: North | H13: =COUNTIF(Customer_Data!$C$2:$C$301,G13) -> 79 | I13: =COUNTIFS(Customer_Data!$C$2:$C$301,G13,Customer_Data!$J$2:$J$301,"Yes") -> 19 | J13: =IFERROR(I13/H13,0) -> 0.24050633
A14: One Year | B14: =COUNTIF(Customer_Data!$E$2:$E$301,A14) -> 89 | C14: =COUNTIFS(Customer_Data!$E$2:$E$301,A14,Customer_Data!$J$2:$J$301,"Yes") -> 14 | D14: =IFERROR(C14/B14,0) -> 0.15730337 | E14: =SUMIFS(Customer_Data!$L$2:$L$301,Customer_Data!$E$2:$E$301,A14,Customer_Data!$J$2:$J$301,"Yes") -> 1349.13 | G14: South | H14: =COUNTIF(Customer_Data!$C$2:$C$301,G14) -> 72 | I14: =COUNTIFS(Customer_Data!$C$2:$C$301,G14,Customer_Data!$J$2:$J$301,"Yes") -> 16 | J14: =IFERROR(I14/H14,0) -> 0.22222222
A15: Two Year | B15: =COUNTIF(Customer_Data!$E$2:$E$301,A15) -> 43 | C15: =COUNTIFS(Customer_Data!$E$2:$E$301,A15,Customer_Data!$J$2:$J$301,"Yes") -> 6 | D15: =IFERROR(C15/B15,0) -> 0.13953488 | E15: =SUMIFS(Customer_Data!$L$2:$L$301,Customer_Data!$E$2:$E$301,A15,Customer_Data!$J$2:$J$301,"Yes") -> 440.58 | G15: East | H15: =COUNTIF(Customer_Data!$C$2:$C$301,G15) -> 71 | I15: =COUNTIFS(Customer_Data!$C$2:$C$301,G15,Customer_Data!$J$2:$J$301,"Yes") -> 16 | J15: =IFERROR(I15/H15,0) -> 0.22535211
G16: West | H16: =COUNTIF(Customer_Data!$C$2:$C$301,G16) -> 78 | I16: =COUNTIFS(Customer_Data!$C$2:$C$301,G16,Customer_Data!$J$2:$J$301,"Yes") -> 14 | J16: =IFERROR(I16/H16,0) -> 0.17948718
A19: CHURN BY TENURE | G19: CHURN BY CUSTOMER TYPE
A20: Tenure | B20: Customers | C20: Churned | D20: Churn Rate | E20: Revenue at Risk | G20: Type | H20: Customers | I20: Churned | J20: Churn Rate | K20: Revenue at Risk
A21: 0-6 | B21: =COUNTIFS(Customer_Data!$F$2:$F$301,">=0",Customer_Data!$F$2:$F$301,"<=6") -> 60 | C21: =COUNTIFS(Customer_Data!$F$2:$F$301,">=0",Customer_Data!$F$2:$F$301,"<=6",Customer_Data!$J$2:$J$301,"Yes") -> 24 | D21: =IFERROR(C21/B21,0) -> 0.4 | E21: =SUMIFS(Customer_Data!$L$2:$L$301,Customer_Data!$F$2:$F$301,">=0",Customer_Data!$F$2:$F$301,"<=6",Customer_Data!$J$2:$J$301,"Yes") -> 2295.37 | G21: Individual | H21: =COUNTIF(Customer_Data!$D$2:$D$301,G21) -> 120 | I21: =COUNTIFS(Customer_Data!$D$2:$D$301,G21,Customer_Data!$J$2:$J$301,"Yes") -> 27 | J21: =IFERROR(I21/H21,0) -> 0.225 | K21: =SUMIFS(Customer_Data!$L$2:$L$301,Customer_Data!$D$2:$D$301,G21,Customer_Data!$J$2:$J$301,"Yes") -> 1301.36
A22: 7-12 | B22: =COUNTIFS(Customer_Data!$F$2:$F$301,">=7",Customer_Data!$F$2:$F$301,"<=12") -> 40 | C22: =COUNTIFS(Customer_Data!$F$2:$F$301,">=7",Customer_Data!$F$2:$F$301,"<=12",Customer_Data!$J$2:$J$301,"Yes") -> 8 | D22: =IFERROR(C22/B22,0) -> 0.2 | E22: =SUMIFS(Customer_Data!$L$2:$L$301,Customer_Data!$F$2:$F$301,">=7",Customer_Data!$F$2:$F$301,"<=12",Customer_Data!$J$2:$J$301,"Yes") -> 903.73 | G22: Small Business | H22: =COUNTIF(Customer_Data!$D$2:$D$301,G22) -> 97 | I22: =COUNTIFS(Customer_Data!$D$2:$D$301,G22,Customer_Data!$J$2:$J$301,"Yes") -> 26 | J22: =IFERROR(I22/H22,0) -> 0.26804124 | K22: =SUMIFS(Customer_Data!$L$2:$L$301,Customer_Data!$D$2:$D$301,G22,Customer_Data!$J$2:$J$301,"Yes") -> 2651.91
A23: 13-24 | B23: =COUNTIFS(Customer_Data!$F$2:$F$301,">=13",Customer_Data!$F$2:$F$301,"<=24") -> 78 | C23: =COUNTIFS(Customer_Data!$F$2:$F$301,">=13",Customer_Data!$F$2:$F$301,"<=24",Customer_Data!$J$2:$J$301,"Yes") -> 10 | D23: =IFERROR(C23/B23,0) -> 0.12820513 | E23: =SUMIFS(Customer_Data!$L$2:$L$301,Customer_Data!$F$2:$F$301,">=13",Customer_Data!$F$2:$F$301,"<=24",Customer_Data!$J$2:$J$301,"Yes") -> 857.46 | G23: Enterprise | H23: =COUNTIF(Customer_Data!$D$2:$D$301,G23) -> 83 | I23: =COUNTIFS(Customer_Data!$D$2:$D$301,G23,Customer_Data!$J$2:$J$301,"Yes") -> 12 | J23: =IFERROR(I23/H23,0) -> 0.14457831 | K23: =SUMIFS(Customer_Data!$L$2:$L$301,Customer_Data!$D$2:$D$301,G23,Customer_Data!$J$2:$J$301,"Yes") -> 2400.22
A24: 25+ | B24: =COUNTIFS(Customer_Data!$F$2:$F$301,">=25",Customer_Data!$F$2:$F$301,"<=999") -> 122 | C24: =COUNTIFS(Customer_Data!$F$2:$F$301,">=25",Customer_Data!$F$2:$F$301,"<=999",Customer_Data!$J$2:$J$301,"Yes") -> 23 | D24: =IFERROR(C24/B24,0) -> 0.18852459 | E24: =SUMIFS(Customer_Data!$L$2:$L$301,Customer_Data!$F$2:$F$301,">=25",Customer_Data!$F$2:$F$301,"<=999",Customer_Data!$J$2:$J$301,"Yes") -> 2296.93
G26: DATA QUALITY CHECK
G27: Blank Customer IDs | H27: =COUNTBLANK(Customer_Data!A2:A301) -> 0
G28: Blank Regions | H28: =COUNTBLANK(Customer_Data!C2:C301) -> 0
G29: Blank Churn Status | H29: =COUNTBLANK(Customer_Data!J2:J301) -> 0
G30: Negative Charges | H30: =COUNTIF(Customer_Data!G2:G301,"<0") -> 0

Sheet Dashboard
A1: CUSTOMER CHURN DASHBOARD
A3: Customers | D3: Churned | G3: Churn Rate | J3: Revenue at Risk
A4: =Analysis!B4 -> 300 | D4: =Analysis!B5 -> 65 | G4: =Analysis!B6 -> 0.21666667 | J4: =Analysis!B7 -> 6353.49
A7: Customer churn overview
A8: The charts highlight the customer segments with higher churn risk.
